#VRML_SIM R2021a utf8
# license: Copyright Cyberbotics Ltd. Licensed for use only with Webots.
# license url: https://cyberbotics.com/webots_assets_license
# Front Group of the mona esp mobile robot.

PROTO MonaFrontGroup [
  field SFVec3f    translation  0 0 0
  field SFRotation rotation     0 1 0 0
]
{
  Transform {
    translation IS translation
    rotation IS rotation
    children [
      MonaCarriage {
        translation 0 -0.002 0
        rotation -0.5771968951617173 -0.5771968951617173 0.577656895078166 -2.093935307179586
      }
      MonaBattery {
        translation -0.016 -0.005 0
      }
      BallJoint {
        jointParameters BallJointParameters {
          anchor -0.002 -0.018 0
        }
        endPoint MonaMarble {
          translation -0.002 -0.018 0
          rotation -0.7302280539212073 0.3425553022630667 0.5911199997952239 1.7480592399579535
        }
      }
    ]
  }
}
